Workbook

Sheet Extrato_Limpo
A1: Data | B1: Descrição | C1: Tipo | D1: Valor (R$) | E1: Ref. Interna | F1: Banco | G1: Categoria | H1: Operacional | I1: Mês
A2: 45931 | B2: ENERGIA ELÉTRICA ESCRITÓRIO | C2: TED Enviada | D2: -16707.86 | F2: Itaú | G2: Utilities | H2: Sim | I2: Out/25
A3: 45931 | B3: SEGURO EMPRESARIAL | C3: Débito Automático | D3: -13461.04 | E3: REF-47056 | F3: BTG | G3: Seguros | H3: Sim | I3: Out/25
A4: 45932 | B4: ENERGIA ELÉTRICA ESCRITÓRIO | C4: Boleto Pago | D4: -41963.14 | F4: Itaú | G4: Utilities | H4: Sim | I4: Out/25
A5: 45933 | B5: AWS SERVICES - INFRAESTRUTURA | C5: Boleto Pago | D5: -59574.82 | E5: REF-32962 | F5: BTG | G5: Infraestrutura Cloud | H5: Sim | I5: Out/25
A6: 45934 | B6: VIAGEM SP-BH EQUIPE COMERCIAL | C6: Boleto Pago | D6: -12897.84 | F6: Itaú | G6: Viagens | H6: Sim | I6: Out/25
A7: 45934 | B7: MATERIAL ESCRITÓRIO | C7: Tarifa Bancária | D7: -30003.49 | F7: BTG | G7: Outros | H7: Sim | I7: Out/25
A8: 45934 | B8: SEGURO EMPRESARIAL | C8: TED Enviada | D8: -32085.34 | E8: REF-11792 | F8: Inter | G8: Seguros | H8: Sim | I8: Out/25
A9: 45935 | B9: VIAGEM SP-BH EQUIPE COMERCIAL | C9: Boleto Pago | D9: -3445.39 | E9: REF-84341 | F9: Itaú | G9: Viagens | H9: Sim | I9: Out/25
A10: 45936 | B10: RENDIMENTO APLICAÇÃO CDB | C10: PIX Recebido | D10: 2065.96 | E10: REF-27987 | F10: Itaú | G10: Receita Financeira | H10: Não | I10: Out/25
A11: 45937 | B11: ENERGIA ELÉTRICA ESCRITÓRIO | C11: PIX Enviado | D11: -43620.33 | E11: REF-40982 | F11: Itaú | G11: Utilities | H11: Sim | I11: Out/25
A12: 45937 | B12: PGTO FREELANCER DEV - PJ | C12: Tarifa Bancária | D12: -7505.76 | E12: REF-20500 | F12: Itaú | G12: Freelancers/Fornecedores | H12: Sim | I12: Out/25
A13: 45937 | B13: PLANO SAÚDE EQUIPE | C13: Débito Automático | D13: -5065.15 | F13: Itaú | G13: Benefícios | H13: Sim | I13: Out/25
A14: 45937 | B14: CLIENTE ALPHA TECH LTDA - NF 1042 | C14: PIX Recebido | D14: 352660.3 | E14: REF-73532 | F14: Itaú | G14: Receita de Cliente | H14: Sim | I14: Out/25
A15: 45938 | B15: ENERGIA ELÉTRICA ESCRITÓRIO | C15: Tarifa Bancária | D15: -15169.25 | F15: Itaú | G15: Utilities | H15: Sim | I15: Out/25
A16: 45939 | B16: AWS SERVICES - INFRAESTRUTURA | C16: TED Enviada | D16: -49226.53 | E16: REF-84668 | F16: Itaú | G16: Infraestrutura Cloud | H16: Sim | I16: Out/25
A17: 45939 | B17: SALÁRIOS E ENCARGOS - FOLHA | C17: Tarifa Bancária | D17: -224061.2 | F17: Itaú | G17: Pessoal | H17: Sim | I17: Out/25
A18: 45940 | B18: SLACK - LICENÇA ENTERPRISE | C18: Tarifa Bancária | D18: -29922.65 | E18: REF-65723 | F18: Itaú | G18: SaaS/Ferramentas | H18: Sim | I18: Out/25
A19: 45941 | B19: PLANO SAÚDE EQUIPE | C19: TED Enviada | D19: -34072.4 | F19: Itaú | G19: Benefícios | H19: Sim | I19: Out/25
A20: 45942 | B20: SLACK - LICENÇA ENTERPRISE | C20: PIX Enviado | D20: -657.78 | E20: REF-93507 | F20: Itaú | G20: SaaS/Ferramentas | H20: Sim | I20: Out/25
A21: 45942 | B21: TRANSFERÊNCIA PARA CONTA RESERVA | C21: Transferência Interna | D21: -294218.66 | F21: Itaú | G21: Transferência Interna | H21: Não | I21: Out/25
A22: 45942 | B22: SALÁRIOS E ENCARGOS - FOLHA | C22: Débito Automático | D22: -186759.51 | E22: REF-27054 | F22: Inter | G22: Pessoal | H22: Sim | I22: Out/25
A23: 45943 | B23: GITHUB ENTERPRISE | C23: Boleto Pago | D23: -7738.11 | E23: REF-97841 | F23: Itaú | G23: SaaS/Ferramentas | H23: Sim | I23: Out/25
A24: 45944 | B24: IMPOSTOS DAS/SIMPLES | C24: Tarifa Bancária | D24: -36345.99 | E24: REF-84177 | F24: Itaú | G24: Impostos | H24: Sim | I24: Out/25
A25: 45944 | B25: RENDIMENTO APLICAÇÃO CDB | C25: TED Recebida | D25: 4969.31 | E25: REF-96275 | F25: BTG | G25: Receita Financeira | H25: Não | I25: Out/25
A26: 45945 | B26: IMPOSTOS DAS/SIMPLES | C26: TED Enviada | D26: -3077.67 | E26: REF-20322 | F26: Itaú | G26: Impostos | H26: Sim | I26: Out/25
A27: 45945 | B27: SALÁRIOS E ENCARGOS - FOLHA | C27: TED Enviada | D27: -232790.6 | E27: REF-98647 | F27: BTG | G27: Pessoal | H27: Sim | I27: Out/25
A28: 45945 | B28: CLIENTE BETA SAAS S.A. - NF 1038 | C28: TED Recebida | D28: 258366.36 | E28: REF-79066 | F28: Itaú | G28: Receita de Cliente | H28: Sim | I28: Out/25
A29: 45947 | B29: ESTORNO COBRANÇA INDEVIDA | C29: Estorno | D29: 728.83 | E29: REF-26614 | F29: BTG | G29: Estorno | H29: Não | I29: Out/25
A30: 45947 | B30: CLIENTE THETA LABS - NF 1070 | C30: Crédito Investimento | D30: 209278.73 | E30: REF-88301 | F30: Inter | G30: Receita de Cliente | H30: Sim | I30: Out/25
A31: 45948 | B31: AWS SERVICES - INFRAESTRUTURA | C31: Tarifa Bancária | D31: -84273.55 | E31: REF-68008 | F31: Inter | G31: Infraestrutura Cloud | H31: Sim | I31: Out/25
A32: 45948 | B32: REEMBOLSO VIAGEM CONF TECH | C32: Crédito Investimento | D32: 59760.39 | E32: REF-64377 | F32: BTG | G32: Viagens | H32: Sim | I32: Out/25
A33: 45948 | B33: HUBSPOT - LICENÇA MENSAL | C33: PIX Enviado | D33: -12076.96 | E33: REF-69598 | F33: Itaú | G33: SaaS/Ferramentas | H33: Sim | I33: Out/25
A34: 45948 | B34: CLIENTE ALPHA TECH LTDA - NF 1042 | C34: TED Recebida | D34: 378460.55 | F34: Itaú | G34: Receita de Cliente | H34: Sim | I34: Out/25
A35: 45950 | B35: CLIENTE DELTA CLOUD - NF 1055 | C35: PIX Recebido | D35: 220930.15 | E35: REF-51104 | F35: Itaú | G35: Receita de Cliente | H35: Sim | I35: Out/25
A36: 45951 | B36: ENERGIA ELÉTRICA ESCRITÓRIO | C36: Débito Automático | D36: -25460.36 | F36: Itaú | G36: Utilities | H36: Sim | I36: Out/25
A37: 45952 | B37: IMPOSTOS DAS/SIMPLES | C37: Tarifa Bancária | D37: -30041.5 | E37: REF-22240 | F37: Itaú | G37: Impostos | H37: Sim | I37: Out/25
A38: 45952 | B38: ALUGUEL COWORKING BERRINI | C38: TED Enviada | D38: -17788.32 | F38: Itaú | G38: Aluguel e Facilities | H38: Sim | I38: Out/25
A39: 45952 | B39: AWS SERVICES - INFRAESTRUTURA | C39: PIX Enviado | D39: -44462.48 | F39: Itaú | G39: Infraestrutura Cloud | H39: Sim | I39: Out/25
A40: 45953 | B40: ALUGUEL COWORKING BERRINI | C40: Boleto Pago | D40: -17050.02 | E40: REF-36071 | F40: Itaú | G40: Aluguel e Facilities | H40: Sim | I40: Out/25
...

Sheet ERP_Limpo
A1: Data Lançamento | B1: Data Competência | C1: Descrição | D1: Centro de Custo | E1: Categoria (Original) | F1: Valor (R$) | G1: Tipo | H1: NF/Doc | I1: Status | J1: Fornecedor/Cliente | K1: Categoria_Corrigida | L1: Flag_Competencia | M1: Flag_NF_Duplicada | N1: Flag_Sem_Doc | O1: Mês_Competencia
A2: 45931 | B2: 45931 | C2: Porto Seguro - Viagens | D2: Infraestrutura | E2: Viagens | F2: -215618.48 | G2: Despesa | H2: DOC-8527 | I2: Divergente | J2: Porto Seguro | K2: Seguros | O2: Out/25
A3: 45931 | B3: 45931 | C3: Kappa Pay - Receita de Consultoria | D3: Comercial | E3: Receita de Consultoria | F3: 246839.92 | G3: Receita | H3: NF-1074 | I3: Em Aberto | J3: Kappa Pay | K3: Receita de Consultoria | M3: DUPLICADA | O3: Out/25
A4: 45932 | B4: 45932 | C4: GitHub - Pessoal | D4: Marketing | E4: Pessoal | F4: -175574.61 | G4: Despesa | H4: DOC-8958 | I4: Pendente | J4: GitHub | K4: SaaS/Ferramentas | O4: Out/25
A5: 45932 | B5: 45932 | C5: Kappa Pay - Receita de Setup | D5: Comercial | E5: Receita de Setup | F5: 158793.6 | G5: Receita | H5: NF-1055 | I5: Pendente | J5: Kappa Pay | K5: Receita de Setup | M5: DUPLICADA | O5: Out/25
A6: 45932 | B6: 45932 | C6: Alpha Tech - Outras Receitas | D6: Comercial | E6: Outras Receitas | F6: 179780.66 | G6: Receita | H6: NF-1070 | I6: Divergente | J6: Alpha Tech | K6: Outras Receitas | O6: Out/25
A7: 45933 | B7: 45933 | C7: Beta SaaS - Receita Recorrente (MRR) | D7: Comercial | E7: Receita Recorrente (MRR) | F7: 159022.17 | G7: Receita | H7: NF-1073 | I7: Conciliado | J7: Beta SaaS | K7: Receita Recorrente (MRR) | O7: Out/25
A8: 45934 | B8: 45904 | C8: Slack - Impostos | D8: Marketing | E8: Impostos | F8: -107673.43 | G8: Despesa | I8: Conciliado | J8: Slack | K8: SaaS/Ferramentas | L8: DIVERGENTE | N8: SEM DOCUMENTO | O8: Set/25
A9: 45936 | B9: 45936 | C9: Porto Seguro - Freelancers/PJ | D9: Comercial | E9: Freelancers/PJ | F9: -80720.93 | G9: Despesa | H9: DOC-6235 | I9: Em Aberto | J9: Porto Seguro | K9: Seguros | O9: Out/25
A10: 45938 | B10: 45938 | C10: Google Cloud - Freelancers/PJ | D10: Infraestrutura | E10: Freelancers/PJ | F10: -244353.45 | G10: Despesa | I10: Conciliado | J10: Google Cloud | K10: Infraestrutura Cloud | N10: SEM DOCUMENTO | O10: Out/25
A11: 45938 | B11: 45908 | C11: ContaAzul - SaaS/Ferramentas | D11: CS/Suporte | E11: SaaS/Ferramentas | F11: -169848.16 | G11: Despesa | H11: DOC-5384 | I11: Em Aberto | J11: ContaAzul | K11: SaaS/Ferramentas | L11: DIVERGENTE | O11: Set/25
A12: 45938 | B12: 45908 | C12: Datadog - Benefícios | D12: Marketing | E12: Benefícios | F12: -42510.15 | G12: Despesa | H12: DOC-7397 | I12: Conciliado | J12: Datadog | K12: SaaS/Ferramentas | L12: DIVERGENTE | O12: Set/25
A13: 45938 | B13: 45878 | C13: Slack - Benefícios | D13: Infraestrutura | E13: Benefícios | F13: -245674.83 | G13: Despesa | H13: DOC-6423 | I13: Conciliado | J13: Slack | K13: SaaS/Ferramentas | L13: DIVERGENTE | O13: Ago/25
A14: 45939 | B14: 45879 | C14: Freelancer A - Pessoal | D14: CS/Suporte | E14: Pessoal | F14: -125076.15 | G14: Despesa | H14: DOC-6982 | I14: Conciliado | J14: Freelancer A | K14: Freelancers/PJ | L14: DIVERGENTE | O14: Ago/25
A15: 45940 | B15: 45940 | C15: ContaAzul - Infraestrutura Cloud | D15: Marketing | E15: Infraestrutura Cloud | F15: -248533.85 | G15: Despesa | H15: DOC-5565 | I15: Em Aberto | J15: ContaAzul | K15: SaaS/Ferramentas | O15: Out/25
A16: 45940 | B16: 45910 | C16: Freelancer A - Infraestrutura Cloud | D16: Produto | E16: Infraestrutura Cloud | F16: -129145.56 | G16: Despesa | H16: DOC-8023 | I16: Conciliado | J16: Freelancer A | K16: Freelancers/PJ | L16: DIVERGENTE | O16: Set/25
A17: 45940 | B17: 45940 | C17: Slack - Freelancers/PJ | D17: Produto | E17: Freelancers/PJ | F17: -202420.02 | G17: Despesa | I17: Divergente | J17: Slack | K17: SaaS/Ferramentas | N17: SEM DOCUMENTO | O17: Out/25
A18: 45941 | B18: 45941 | C18: Zeta AI - Receita Recorrente (MRR) | D18: Comercial | E18: Receita Recorrente (MRR) | F18: 291570.66 | G18: Receita | H18: NF-1071 | I18: Conciliado | J18: Zeta AI | K18: Receita Recorrente (MRR) | M18: DUPLICADA | O18: Out/25
A19: 45941 | B19: 45881 | C19: Freelancer A - Aluguel e Facilities | D19: CS/Suporte | E19: Aluguel e Facilities | F19: -18839.92 | G19: Despesa | H19: DOC-8112 | I19: Pendente | J19: Freelancer A | K19: Freelancers/PJ | L19: DIVERGENTE | O19: Ago/25
A20: 45941 | B20: 45911 | C20: Delta Cloud - Receita de Consultoria | D20: Comercial | E20: Receita de Consultoria | F20: 16279.8 | G20: Receita | H20: NF-1044 | I20: Conciliado | J20: Delta Cloud | K20: Receita de Consultoria | L20: DIVERGENTE | O20: Set/25
A21: 45941 | B21: 45941 | C21: Silva & Advogados - SaaS/Ferramentas | D21: Engenharia | E21: SaaS/Ferramentas | F21: -99387.22 | G21: Despesa | H21: DOC-6918 | I21: Conciliado | J21: Silva & Advogados | K21: Jurídico e Contabilidade | O21: Out/25
A22: 45941 | B22: 45911 | C22: Gamma Digital - Outras Receitas | D22: Engenharia | E22: Outras Receitas | F22: 30816.52 | G22: Receita | H22: NF-1066 | I22: Conciliado | J22: Gamma Digital | K22: Outras Receitas | L22: DIVERGENTE | O22: Set/25
A23: 45942 | B23: 45912 | C23: Silva & Advogados - Freelancers/PJ | D23: CS/Suporte | E23: Freelancers/PJ | F23: -89876.57 | G23: Despesa | I23: Pendente | J23: Silva & Advogados | K23: Jurídico e Contabilidade | L23: DIVERGENTE | N23: SEM DOCUMENTO | O23: Set/25
A24: 45943 | B24: 45913 | C24: Slack - Aluguel e Facilities | D24: Infraestrutura | E24: Aluguel e Facilities | F24: -171493.52 | G24: Despesa | H24: DOC-7220 | I24: Conciliado | J24: Slack | K24: SaaS/Ferramentas | L24: DIVERGENTE | O24: Set/25
A25: 45943 | B25: 45943 | C25: Beta SaaS - Receita de Setup | D25: Comercial | E25: Receita de Setup | F25: 209819.43 | G25: Receita | H25: NF-1063 | I25: Conciliado | J25: Beta SaaS | K25: Receita de Setup | M25: DUPLICADA | O25: Out/25
A26: 45944 | B26: 45944 | C26: Slack - Aluguel e Facilities | D26: Marketing | E26: Aluguel e Facilities | F26: -130532.26 | G26: Despesa | H26: DOC-7189 | I26: Divergente | J26: Slack | K26: SaaS/Ferramentas | O26: Out/25
A27: 45944 | B27: 45944 | C27: GitHub - Viagens | D27: Engenharia | E27: Viagens | F27: -134213.17 | G27: Despesa | H27: DOC-6700 | I27: Conciliado | J27: GitHub | K27: SaaS/Ferramentas | O27: Out/25
A28: 45945 | B28: 45885 | C28: Porto Seguro - Seguros | D28: Engenharia | E28: Seguros | F28: -156591.03 | G28: Despesa | H28: DOC-6176 | I28: Conciliado | J28: Porto Seguro | K28: Seguros | L28: DIVERGENTE | O28: Ago/25
A29: 45946 | B29: 45886 | C29: HubSpot - Impostos | D29: Engenharia | E29: Impostos | F29: -57622.24 | G29: Despesa | I29: Divergente | J29: HubSpot | K29: SaaS/Ferramentas | L29: DIVERGENTE | N29: SEM DOCUMENTO | O29: Ago/25
A30: 45946 | B30: 45886 | C30: GitHub - Viagens | D30: G&A | E30: Viagens | F30: -131201.63 | G30: Despesa | H30: DOC-9723 | I30: Pendente | J30: GitHub | K30: SaaS/Ferramentas | L30: DIVERGENTE | O30: Ago/25
A31: 45946 | B31: 45946 | C31: Epsilon Data - Receita Recorrente (MRR) | D31: Comercial | E31: Receita Recorrente (MRR) | F31: 79182.17 | G31: Receita | H31: NF-1084 | I31: Conciliado | J31: Epsilon Data | K31: Receita Recorrente (MRR) | M31: DUPLICADA | O31: Out/25
A32: 45946 | B32: 45946 | C32: AWS - SaaS/Ferramentas | D32: Marketing | E32: SaaS/Ferramentas | F32: -108572.52 | G32: Despesa | H32: DOC-9064 | I32: Pendente | J32: AWS | K32: Infraestrutura Cloud | O32: Out/25
A33: 45947 | B33: 45917 | C33: Google Cloud - Jurídico e Contabilidade | D33: Produto | E33: Jurídico e Contabilidade | F33: -249898.96 | G33: Despesa | H33: DOC-9306 | I33: Conciliado | J33: Google Cloud | K33: Infraestrutura Cloud | L33: DIVERGENTE | O33: Set/25
A34: 45947 | B34: 45947 | C34: WeWork - Impostos | D34: CS/Suporte | E34: Impostos | F34: -129581.32 | G34: Despesa | I34: Divergente | J34: WeWork | K34: Aluguel e Facilities | N34: SEM DOCUMENTO | O34: Out/25
A35: 45947 | B35: 45917 | C35: Freelancer B - Pessoal | D35: Infraestrutura | E35: Pessoal | F35: -6172.46 | G35: Despesa | H35: DOC-9460 | I35: Conciliado | J35: Freelancer B | K35: Freelancers/PJ | L35: DIVERGENTE | O35: Set/25
A36: 45947 | B36: 45947 | C36: GitHub - Freelancers/PJ | D36: CS/Suporte | E36: Freelancers/PJ | F36: -234424.94 | G36: Despesa | I36: Pendente | J36: GitHub | K36: SaaS/Ferramentas | N36: SEM DOCUMENTO | O36: Out/25
A37: 45949 | B37: 45919 | C37: Slack - Freelancers/PJ | D37: Produto | E37: Freelancers/PJ | F37: -122619.95 | G37: Despesa | H37: DOC-7201 | I37: Pendente | J37: Slack | K37: SaaS/Ferramentas | L37: DIVERGENTE | O37: Set/25
A38: 45949 | B38: 45919 | C38: Alpha Tech - Receita de Setup | D38: Comercial | E38: Receita de Setup | F38: 314564.18 | G38: Receita | H38: NF-1063 | I38: Divergente | J38: Alpha Tech | K38: Receita de Setup | L38: DIVERGENTE | M38: DUPLICADA | O38: Set/25
A39: 45950 | B39: 45950 | C39: Iota Systems - Receita de Consultoria | D39: Engenharia | E39: Receita de Consultoria | F39: 279733.74 | G39: Receita | H39: NF-1067 | I39: Conciliado | J39: Iota Systems | K39: Receita de Consultoria | M39: DUPLICADA | O39: Out/25
A40: 45950 | B40: 45950 | C40: WeWork - Infraestrutura Cloud | D40: G&A | E40: Infraestrutura Cloud | F40: -104285.87 | G40: Despesa | H40: DOC-5950 | I40: Divergente | J40: WeWork | K40: Aluguel e Facilities | O40: Out/25
...

Sheet Receita_Completa
A1: SEÇÃO 1 — MRR POR CLIENTE (fonte: Receita_Clientes original)
A2: Cliente | B2: Plano | C2: MRR Contratado (R$) | D2: Out/25 Faturado | E2: Nov/25 Faturado | F2: Dez/25 Faturado | G2: Churn Risk | H2: NF Emitida Out | I2: NF Emitida Nov | J2: NF Emitida Dez
A3: Alpha Tech | B3: Enterprise | C3: 45000 | D3: 45000 | E3: 45000 | F3: 45000 | G3: Baixo | H3: Pendente | I3: Pendente | J3: Pendente
A4: Beta SaaS | B4: Enterprise | C4: 38000 | D4: 38000 | E4: 38000 | F4: 0 | G4: Churned | H4: Emitida | I4: Em atraso | J4: N/A
A5: Gamma Digital | B5: Growth | C5: 22000 | D5: 22000 | E5: 22000 | F5: 22000 | G5: Baixo | H5: Emitida | I5: Pendente | J5: Em atraso
A6: Delta Cloud | B6: Growth | C6: 18000 | D6: 18000 | E6: 15000 | F6: 15000 | G6: Alto | H6: Emitida | I6: Emitida | J6: Pendente
A7: Epsilon Data | B7: Enterprise | C7: 55000 | D7: 55000 | E7: 55000 | F7: 55000 | G7: Baixo | H7: Emitida | I7: Emitida | J7: Emitida
A8: Zeta AI | B8: Growth | C8: 28000 | D8: 28000 | E8: 28000 | F8: 28000 | G8: Médio | H8: Emitida | I8: Emitida | J8: Emitida
A9: Theta Labs | B9: Starter | C9: 8000 | D9: 8000 | E9: 8000 | F9: 8000 | G9: Baixo | H9: Emitida | I9: Emitida | J9: Emitida
A10: Iota Systems | B10: Growth | C10: 15000 | D10: 15000 | E10: 15000 | F10: 15000 | G10: Baixo | H10: Emitida | I10: Pendente | J10: Emitida
A11: Kappa Pay | B11: Enterprise | C11: 42000 | D11: 42000 | E11: 42000 | F11: 42000 | G11: Baixo | H11: Emitida | I11: Em atraso | J11: Emitida
A12: Lambda Fin | B12: Starter | C12: 9500 | D12: 9500 | E12: 9500 | F12: 9500 | G12: Médio | H12: Emitida | I12: Em atraso | J12: Em atraso
A13: Mu Analytics | B13: Growth | C13: 19000 | D13: 0 | E13: 19000 | F13: 19000 | G13: Baixo | H13: Pendente | I13: Emitida | J13: Pendente
A14: Nu Robotics | B14: Enterprise | C14: 60000 | D14: 60000 | E14: 60000 | F14: 60000 | G14: Baixo | H14: Emitida | I14: Em atraso | J14: Pendente
... A17: Rho Security | B17: Enterprise | C17: 50000 | D17: 50000 | E17: 50000 | F17: 50000 | G17: Baixo | H17: Pendente | I17: Em atraso | J17: Em atraso
A18: TOTAL | C18: 442000 | D18: 423000 | E18: 439000 | F18: 401000
A19: TOTAL | C19: =SUM(C3:C18) -> 884000 | D19: =SUM(D3:D18) -> 846000 | E19: =SUM(E3:E18) -> 878000 | F19: =SUM(F3:F18) -> 802000
A22: SEÇÃO 2 — RECEITA TOTAL POR CLIENTE (Q4 2025)
A23: Cliente | B23: MRR Q4 (Faturado) | C23: Receita ERP Q4 | D23: Receita Extrato Q4 | E23: Delta ERP vs Extrato | F23: Obs.
A24: Alpha Tech | B24: 135000 | C24: =SUMIFS(ERP_Limpo!F:F,ERP_Limpo!G:G,"Receita",ERP_Limpo!J:J,"Alpha Tech") -> 1172889.2 | D24: =SUMIFS(Extrato_Limpo!D:D,Extrato_Limpo!G:G,"Receita de Cliente",Extrato_Limpo!B:B,"*ALPHA TECH*") -> 2040122.6 | E24: =C24-D24 -> -867233.42
A25: Beta SaaS | B25: 76000 | C25: =SUMIFS(ERP_Limpo!F:F,ERP_Limpo!G:G,"Receita",ERP_Limpo!J:J,"Beta SaaS") -> 1039795.8 | D25: =SUMIFS(Extrato_Limpo!D:D,Extrato_Limpo!G:G,"Receita de Cliente",Extrato_Limpo!B:B,"*BETA SAAS*") -> 1261517.7 | E25: =C25-D25 -> -221721.85
A26: Gamma Digital | B26: 66000 | C26: =SUMIFS(ERP_Limpo!F:F,ERP_Limpo!G:G,"Receita",ERP_Limpo!J:J,"Gamma Digital") -> 433638.01 | D26: =SUMIFS(Extrato_Limpo!D:D,Extrato_Limpo!G:G,"Receita de Cliente",Extrato_Limpo!B:B,"*GAMMA DIGITAL*") -> 321814.66 | E26: =C26-D26 -> 111823.35
A27: Delta Cloud | B27: 48000 | C27: =SUMIFS(ERP_Limpo!F:F,ERP_Limpo!G:G,"Receita",ERP_Limpo!J:J,"Delta Cloud") -> 1795333.9 | D27: =SUMIFS(Extrato_Limpo!D:D,Extrato_Limpo!G:G,"Receita de Cliente",Extrato_Limpo!B:B,"*DELTA CLOUD*") -> 787246.79 | E27: =C27-D27 -> 1008087.1
A28: Epsilon Data | B28: 165000 | C28: =SUMIFS(ERP_Limpo!F:F,ERP_Limpo!G:G,"Receita",ERP_Limpo!J:J,"Epsilon Data") -> 1448477.7 | D28: =SUMIFS(Extrato_Limpo!D:D,Extrato_Limpo!G:G,"Receita de Cliente",Extrato_Limpo!B:B,"*EPSILON DATA*") -> 1249542.4 | E28: =C28-D28 -> 198935.27
A29: Zeta AI | B29: 84000 | C29: =SUMIFS(ERP_Limpo!F:F,ERP_Limpo!G:G,"Receita",ERP_Limpo!J:J,"Zeta AI") -> 1175077.9 | D29: =SUMIFS(Extrato_Limpo!D:D,Extrato_Limpo!G:G,"Receita de Cliente",Extrato_Limpo!B:B,"*ZETA AI*") -> 767954.55 | E29: =C29-D29 -> 407123.3
A30: Theta Labs | B30: 24000 | C30: =SUMIFS(ERP_Limpo!F:F,ERP_Limpo!G:G,"Receita",ERP_Limpo!J:J,"Theta Labs") -> 2093472.4 | D30: =SUMIFS(Extrato_Limpo!D:D,Extrato_Limpo!G:G,"Receita de Cliente",Extrato_Limpo!B:B,"*THETA LABS*") -> 810227.85 | E30: =C30-D30 -> 1283244.5
A31: Iota Systems | B31: 45000 | C31: =SUMIFS(ERP_Limpo!F:F,ERP_Limpo!G:G,"Receita",ERP_Limpo!J:J,"Iota Systems") -> 1440103.4 | D31: =SUMIFS(Extrato_Limpo!D:D,Extrato_Limpo!G:G,"Receita de Cliente",Extrato_Limpo!B:B,"*IOTA SYSTEMS*") -> 954824.86 | E31: =C31-D31 -> 485278.57
A32: Kappa Pay | B32: 126000 | C32: =SUMIFS(ERP_Limpo!F:F,ERP_Limpo!G:G,"Receita",ERP_Limpo!J:J,"Kappa Pay") -> 909500.53 | D32: =SUMIFS(Extrato_Limpo!D:D,Extrato_Limpo!G:G,"Receita de Cliente",Extrato_Limpo!B:B,"*KAPPA PAY*") -> 1596633.3 | E32: =C32-D32 -> -687132.81
A33: Lambda Fin | B33: 28500 | C33: =SUMIFS(ERP_Limpo!F:F,ERP_Limpo!G:G,"Receita",ERP_Limpo!J:J,"Lambda Fin") -> 0 | D33: 0 | E33: =C33-D33 -> 0 | F33: Sem recebimento no extrato Q4 — possível inadimplência
A34: Mu Analytics | B34: 38000 | C34: =SUMIFS(ERP_Limpo!F:F,ERP_Limpo!G:G,"Receita",ERP_Limpo!J:J,"Mu Analytics") -> 0 | D34: 0 | E34: =C34-D34 -> 0 | F34: Sem recebimento no extrato Q4 — possível inadimplência
A35: Nu Robotics | B35: 180000 | C35: =SUMIFS(ERP_Limpo!F:F,ERP_Limpo!G:G,"Receita",ERP_Limpo!J:J,"Nu Robotics") -> 0 | D35: 0 | E35: =C35-D35 -> 0 | F35: Sem recebimento no extrato Q4 — possível inadimplência
A36: Omicron Health | B36: 75000 | C36: =SUMIFS(ERP_Limpo!F:F,ERP_Limpo!G:G,"Receita",ERP_Limpo!J:J,"Omicron Health") -> 0 | D36: 0 | E36: =C36-D36 -> 0 | F36: Sem recebimento no extrato Q4 — possível inadimplência
A37: Pi Logistics | B37: 22500 | C37: =SUMIFS(ERP_Limpo!F:F,ERP_Limpo!G:G,"Receita",ERP_Limpo!J:J,"Pi Logistics") -> 0 | D37: 0 | E37: =C37-D37 -> 0 | F37: Sem recebimento no extrato Q4 — possível inadimplência
A38: Rho Security | B38: 150000 | C38: =SUMIFS(ERP_Limpo!F:F,ERP_Limpo!G:G,"Receita",ERP_Limpo!J:J,"Rho Security") -> 0 | D38: 0 | E38: =C38-D38 -> 0 | F38: Sem recebimento no extrato Q4 — possível inadimplência
A39: TOTAL | B39: =SUM(B24:B38) -> 1263000 | C39: =SUM(C24:C38) -> 11508289 | D39: =SUM(D24:D38) -> 9789884.7
A42: SEÇÃO 3 — CLIENTES SEM RECEBIMENTO NO EXTRATO Q4
A43: Cliente | B43: MRR Q4 Faturado | C43: Risco Churn | D43: Observação
A44: Lambda Fin | B44: 28500 | C44: Médio | D44: Nenhum recebimento no extrato Q4
A45: Mu Analytics | B45: 38000 | C45: Baixo | D45: Nenhum recebimento no extrato Q4
A46: Nu Robotics | B46: 180000 | C46: Baixo | D46: Nenhum recebimento no extrato Q4
...

Sheet DRE_Corrigida
A1: DRE CORRIGIDA — NUVIO TECH (Q4 2025)
B2: Out/25 | C2: Nov/25 | D2: Dez/25 | E2: Q4 2025 | F2: DRE Original (Out) | G2: Fonte/Nota
A3: Receita Bruta | B3: =SUMIFS(ERP_Limpo!F:F,ERP_Limpo!G:G,"Receita",ERP_Limpo!O:O,"Out/25") -> 4432710.5 | C3: =SUMIFS(ERP_Limpo!F:F,ERP_Limpo!G:G,"Receita",ERP_Limpo!O:O,"Nov/25") -> 3956495.7 | D3: =SUMIFS(ERP_Limpo!F:F,ERP_Limpo!G:G,"Receita",ERP_Limpo!O:O,"Dez/25") -> 2309191.5 | E3: =SUM(B3:D3) -> 10698398 | F3: 442000 | G3: ERP_Limpo (todas receitas por Data Competência no Q4)
A4: (-) Impostos sobre Receita (est. 7,5%) | B4: =-0.075*B3 -> -332453.29 | C4: =-0.075*C3 -> -296737.18 | D4: =-0.075*D3 -> -173189.36 | E4: =SUM(B4:D4) -> -802379.84 | F4: -33150 | G4: Estimativa: 7,5% Receita Bruta (ERP sem dados de impostos confiáveis)
A5: (-) Deduções e Devoluções | B5: =0 -> 0 | C5: =0 -> 0 | D5: =0 -> 0 | E5: =SUM(B5:D5) -> 0 | F5: -5000 | G5: Sem dados ERP — manter 0 ou ajustar manualmente
A6: (=) Receita Líquida | B6: =SUM(B3,B4,B5) -> 4100257.3 | C6: =SUM(C3,C4,C5) -> 3659758.6 | D6: =SUM(D3,D4,D5) -> 2136002.2 | E6: =SUM(B6:D6) -> 9896018
A8: Custos dos Serviços (COGS)
A9: Infraestrutura Cloud (AWS+GCP) | B9: =SUMIFS(ERP_Limpo!F:F,ERP_Limpo!G:G,"Despesa",ERP_Limpo!K:K,"Infraestrutura Cloud",ERP_Limpo!O:O,"Out/25") -> -1065900.1 | C9: =SUMIFS(ERP_Limpo!F:F,ERP_Limpo!G:G,"Despesa",ERP_Limpo!K:K,"Infraestrutura Cloud",ERP_Limpo!O:O,"Nov/25") -> -1100339.5 | D9: =SUMIFS(ERP_Limpo!F:F,ERP_Limpo!G:G,"Despesa",ERP_Limpo!K:K,"Infraestrutura Cloud",ERP_Limpo!O:O,"Dez/25") -> -298136.63 | E9: =SUM(B9:D9) -> -2464376.2 | F9: -78000 | G9: ERP_Limpo, Categoria_Corrigida=Infraestrutura Cloud
A10: SaaS/Ferramentas (operação) | B10: =SUMIFS(ERP_Limpo!F:F,ERP_Limpo!G:G,"Despesa",ERP_Limpo!K:K,"SaaS/Ferramentas",ERP_Limpo!O:O,"Out/25") -> -2189381.3 | C10: =SUMIFS(ERP_Limpo!F:F,ERP_Limpo!G:G,"Despesa",ERP_Limpo!K:K,"SaaS/Ferramentas",ERP_Limpo!O:O,"Nov/25") -> -2117068.2 | D10: =SUMIFS(ERP_Limpo!F:F,ERP_Limpo!G:G,"Despesa",ERP_Limpo!K:K,"SaaS/Ferramentas",ERP_Limpo!O:O,"Dez/25") -> -1011489.1 | E10: =SUM(B10:D10) -> -5317938.7 | F10: -12000 | G10: ERP_Limpo, Categoria_Corrigida=SaaS/Ferramentas
A11: (=) Lucro Bruto | B11: =SUM(B6,B9,B10) -> 844975.87 | C11: =SUM(C6,C9,C10) -> 442350.77 | D11: =SUM(D6,D9,D10) -> 826376.45 | E11: =SUM(B11:D11) -> 2113703.1
A12: Margem Bruta % | B12: =IF(B6=0,0,B11/B6) -> 0.20607874 | C12: =IF(C6=0,0,C11/C6) -> 0.12086884 | D12: =IF(D6=0,0,D11/D6) -> 0.38687997
A14: Despesas Operacionais
A15: Pessoal (Salários + Encargos) | B15: =SUMIFS(Extrato_Limpo!D:D,Extrato_Limpo!G:G,"Pessoal",Extrato_Limpo!I:I,"Out/25") -> -643611.31 | C15: =SUMIFS(Extrato_Limpo!D:D,Extrato_Limpo!G:G,"Pessoal",Extrato_Limpo!I:I,"Nov/25") -> 0 | D15: =SUMIFS(Extrato_Limpo!D:D,Extrato_Limpo!G:G,"Pessoal",Extrato_Limpo!I:I,"Dez/25") -> -427955.5 | E15: =SUM(B15:D15) -> -1071566.8 | F15: -185000 | G15: Extrato_Limpo (SALÁRIOS E ENCARGOS) — ERP sem dados Pessoal
A16: Benefícios | B16: =SUMIFS(ERP_Limpo!F:F,ERP_Limpo!G:G,"Despesa",ERP_Limpo!K:K,"Benefícios",ERP_Limpo!O:O,"Out/25") -> -378087.33 | C16: =SUMIFS(ERP_Limpo!F:F,ERP_Limpo!G:G,"Despesa",ERP_Limpo!K:K,"Benefícios",ERP_Limpo!O:O,"Nov/25") -> -263581.84 | D16: =SUMIFS(ERP_Limpo!F:F,ERP_Limpo!G:G,"Despesa",ERP_Limpo!K:K,"Benefícios",ERP_Limpo!O:O,"Dez/25") -> -137101.58 | E16: =SUM(B16:D16) -> -778770.75 | F16: -28000 | G16: ERP_Limpo, Categoria_Corrigida=Benefícios
A17: Freelancers / PJ | B17: =SUMIFS(ERP_Limpo!F:F,ERP_Limpo!G:G,"Despesa",ERP_Limpo!K:K,"Freelancers/PJ",ERP_Limpo!O:O,"Out/25") -> -122716.74 | C17: =SUMIFS(ERP_Limpo!F:F,ERP_Limpo!G:G,"Despesa",ERP_Limpo!K:K,"Freelancers/PJ",ERP_Limpo!O:O,"Nov/25") -> -809630.39 | D17: =SUMIFS(ERP_Limpo!F:F,ERP_Limpo!G:G,"Despesa",ERP_Limpo!K:K,"Freelancers/PJ",ERP_Limpo!O:O,"Dez/25") -> -719724.52 | E17: =SUM(B17:D17) -> -1652071.6 | F17: -22000 | G17: ERP_Limpo, Categoria_Corrigida=Freelancers/PJ
A18: Aluguel e Facilities | B18: =SUMIFS(ERP_Limpo!F:F,ERP_Limpo!G:G,"Despesa",ERP_Limpo!K:K,"Aluguel e Facilities",ERP_Limpo!O:O,"Out/25") -> -760465.81 | C18: =SUMIFS(ERP_Limpo!F:F,ERP_Limpo!G:G,"Despesa",ERP_Limpo!K:K,"Aluguel e Facilities",ERP_Limpo!O:O,"Nov/25") -> 0 | D18: =SUMIFS(ERP_Limpo!F:F,ERP_Limpo!G:G,"Despesa",ERP_Limpo!K:K,"Aluguel e Facilities",ERP_Limpo!O:O,"Dez/25") -> -125962.37 | E18: =SUM(B18:D18) -> -886428.18 | F18: -15000 | G18: ERP_Limpo, Categoria_Corrigida=Aluguel e Facilities
A19: Jurídico e Contabilidade | B19: =SUMIFS(ERP_Limpo!F:F,ERP_Limpo!G:G,"Despesa",ERP_Limpo!K:K,"Jurídico e Contabilidade",ERP_Limpo!O:O,"Out/25") -> -292739.24 | C19: =SUMIFS(ERP_Limpo!F:F,ERP_Limpo!G:G,"Despesa",ERP_Limpo!K:K,"Jurídico e Contabilidade",ERP_Limpo!O:O,"Nov/25") -> -514354 | D19: =SUMIFS(ERP_Limpo!F:F,ERP_Limpo!G:G,"Despesa",ERP_Limpo!K:K,"Jurídico e Contabilidade",ERP_Limpo!O:O,"Dez/25") -> -119893.53 | E19: =SUM(B19:D19) -> -926986.77 | F19: -8000 | G19: ERP_Limpo, Categoria_Corrigida=Jurídico e Contabilidade
A20: Viagens | B20: =SUMIFS(ERP_Limpo!F:F,ERP_Limpo!G:G,"Despesa",ERP_Limpo!K:K,"Viagens",ERP_Limpo!O:O,"Out/25") -> 0 | C20: =SUMIFS(ERP_Limpo!F:F,ERP_Limpo!G:G,"Despesa",ERP_Limpo!K:K,"Viagens",ERP_Limpo!O:O,"Nov/25") -> 0 | D20: =SUMIFS(ERP_Limpo!F:F,ERP_Limpo!G:G,"Despesa",ERP_Limpo!K:K,"Viagens",ERP_Limpo!O:O,"Dez/25") -> 0 | E20: =SUM(B20:D20) -> 0 | F20: -5000 | G20: ERP_Limpo, Categoria_Corrigida=Viagens
A21: Seguros | B21: =SUMIFS(ERP_Limpo!F:F,ERP_Limpo!G:G,"Despesa",ERP_Limpo!K:K,"Seguros",ERP_Limpo!O:O,"Out/25") -> -596725.73 | C21: =SUMIFS(ERP_Limpo!F:F,ERP_Limpo!G:G,"Despesa",ERP_Limpo!K:K,"Seguros",ERP_Limpo!O:O,"Nov/25") -> -434342.63 | D21: =SUMIFS(ERP_Limpo!F:F,ERP_Limpo!G:G,"Despesa",ERP_Limpo!K:K,"Seguros",ERP_Limpo!O:O,"Dez/25") -> -515470.84 | E21: =SUM(B21:D21) -> -1546539.2 | F21: -4000 | G21: ERP_Limpo, Categoria_Corrigida=Seguros
A22: Outros / Diversos | B22: =SUMIFS(ERP_Limpo!F:F,ERP_Limpo!G:G,"Despesa",ERP_Limpo!K:K,"Outros",ERP_Limpo!O:O,"Out/25") -> 0 | C22: =SUMIFS(ERP_Limpo!F:F,ERP_Limpo!G:G,"Despesa",ERP_Limpo!K:K,"Outros",ERP_Limpo!O:O,"Nov/25") -> 0 | D22: =SUMIFS(ERP_Limpo!F:F,ERP_Limpo!G:G,"Despesa",ERP_Limpo!K:K,"Outros",ERP_Limpo!O:O,"Dez/25") -> 0 | E22: =SUM(B22:D22) -> 0 | F22: -4000 | G22: ERP_Limpo, Categoria_Corrigida=Outros (categorias não mapeadas)
A23: (=) Total Despesas Operacionais | B23: =SUM(B15,B16,B17,B18,B19,B20,B21,B22) -> -2794346.2 | C23: =SUM(C15,C16,C17,C18,C19,C20,C21,C22) -> -2021908.9 | D23: =SUM(D15,D16,D17,D18,D19,D20,D21,D22) -> -2046108.3 | E23: =SUM(B23:D23) -> -6862363.4
A25: (=) EBITDA | B25: =SUM(B11,B23) -> -1949370.3 | C25: =SUM(C11,C23) -> -1579558.1 | D25: =SUM(D11,D23) -> -1219731.9 | E25: =SUM(B25:D25) -> -4748660.3
A26: Margem EBITDA % | B26: =IF(B6=0,0,B25/B6) -> -0.47542634 | C26: =IF(C6=0,0,C25/C6) -> -0.43160172 | D26: =IF(D6=0,0,D25/D6) -> -0.57103495
A28: Depreciação e Amortização | B28: -3000 | C28: -3000 | D28: -3000 | E28: =SUM(B28:D28) -> -9000 | F28: -3000 | G28: DRE original — sem fonte raw melhor
A29: (=) EBIT | B29: =SUM(B25,B28) -> -1952370.3 | C29: =SUM(C25,C28) -> -1582558.1 | D29: =SUM(D25,D28) -> -1222731.9 | E29: =SUM(B29:D29) -> -4757660.3
A31: Receitas Financeiras | B31: 2500 | C31: 3200 | D31: 2800 | E31: =SUM(B31:D31) -> 8500 | F31: 2500 | G31: DRE original — sem fonte raw melhor
A32: Despesas Financeiras | B32: -1500 | C32: -1800 | D32: -2200 | E32: =SUM(B32:D32) -> -5500 | F32: -1500 | G32: DRE original — sem fonte raw melhor
A33: (=) Resultado Financeiro | B33: =SUM(B31,B32) -> 1000 | C33: =SUM(C31,C32) -> 1400 | D33: =SUM(D31,D32) -> 600 | E33: =SUM(B33:D33) -> 3000
A35: (=) Resultado Antes IR/CS | B35: =SUM(B29,B33) -> -1951370.3 | C35: =SUM(C29,C33) -> -1581158.1 | D35: =SUM(D29,D33) -> -1222131.9 | E35: =SUM(B35:D35) -> -4754660.3
A36: IR/CS | B36: 0 | C36: 0 | D36: 0 | E36: =SUM(B36:D36) -> 0 | F36: 0
A37: (=) Resultado Líquido | B37: =SUM(B35,B36) -> -1951370.3 | C37: =SUM(C35,C36) -> -1581158.1 | D37: =SUM(D35,D36) -> -1222131.9 | E37: =SUM(B37:D37) -> -4754660.3
A38: Margem Líquida % | B38: =IF(B6=0,0,B37/B6) -> -0.47591411 | C38: =IF(C6=0,0,C37/C6) -> -0.43203891 | D38: =IF(D6=0,0,D37/D6) -> -0.57215855

Sheet Caixa_Corrigido
A1: CAIXA CORRIGIDO — NUVIO TECH (Q4 2025) — Fonte: Extrato_Limpo
B2: Out/25 | C2: Nov/25 | D2: Dez/25 | E2: Média Mensal | F2: Caixa Original (Out)
A3: Saldo Inicial | B3: 2850000 | C3: =B15 -> 4201114.7 | D3: =C15 -> 8142026.5 | F3: Saldo implícito derivado do extrato (antes de 01/Out/25). Caixa_Runway original usava R$3.200.000 (diferença: R$350k não explicada).
A5: (+) Entradas Operacionais | B5: =SUMIFS(Extrato_Limpo!D:D,Extrato_Limpo!D:D,">0",Extrato_Limpo!H:H,"Sim",Extrato_Limpo!I:I,"Out/25") -> 2829374.4 | C5: =SUMIFS(Extrato_Limpo!D:D,Extrato_Limpo!D:D,">0",Extrato_Limpo!H:H,"Sim",Extrato_Limpo!I:I,"Nov/25") -> 3765799 | D5: =SUMIFS(Extrato_Limpo!D:D,Extrato_Limpo!D:D,">0",Extrato_Limpo!H:H,"Sim",Extrato_Limpo!I:I,"Dez/25") -> 3904870.7 | E5: =AVERAGE(B5:D5) -> 3500014.7 | F5: Extrato: Valor>0, Operacional=Sim
A6: (-) Saídas Operacionais | B6: =SUMIFS(Extrato_Limpo!D:D,Extrato_Limpo!D:D,"<0",Extrato_Limpo!H:H,"Sim",Extrato_Limpo!I:I,"Out/25") -> -1495421 | C6: =SUMIFS(Extrato_Limpo!D:D,Extrato_Limpo!D:D,"<0",Extrato_Limpo!H:H,"Sim",Extrato_Limpo!I:I,"Nov/25") -> -1334394 | D6: =SUMIFS(Extrato_Limpo!D:D,Extrato_Limpo!D:D,"<0",Extrato_Limpo!H:H,"Sim",Extrato_Limpo!I:I,"Dez/25") -> -1275197.9 | E6: =AVERAGE(B6:D6) -> -1368337.6 | F6: Extrato: Valor<0, Operacional=Sim
A7: (=) Fluxo Caixa Operacional | B7: =B5+B6 -> 1333953.5 | C7: =C5+C6 -> 2431405 | D7: =D5+D6 -> 2629672.7 | E7: =AVERAGE(B7:D7) -> 2131677.1
A9: (+) Aporte de Investidores | B9: =SUMIFS(Extrato_Limpo!D:D,Extrato_Limpo!G:G,"Aporte de Investidor",Extrato_Limpo!I:I,"Out/25") -> 0 | C9: =SUMIFS(Extrato_Limpo!D:D,Extrato_Limpo!G:G,"Aporte de Investidor",Extrato_Limpo!I:I,"Nov/25") -> 1500000 | D9: =SUMIFS(Extrato_Limpo!D:D,Extrato_Limpo!G:G,"Aporte de Investidor",Extrato_Limpo!I:I,"Dez/25") -> 1500000 | E9: =AVERAGE(B9:D9) -> 1000000 | F9: Extrato: Categoria=Aporte de Investidor (não operacional)
A10: (+) Receitas Financeiras | B10: =SUMIFS(Extrato_Limpo!D:D,Extrato_Limpo!G:G,"Receita Financeira",Extrato_Limpo!I:I,"Out/25") -> 10842.55 | C10: =SUMIFS(Extrato_Limpo!D:D,Extrato_Limpo!G:G,"Receita Financeira",Extrato_Limpo!I:I,"Nov/25") -> 0 | D10: =SUMIFS(Extrato_Limpo!D:D,Extrato_Limpo!G:G,"Receita Financeira",Extrato_Limpo!I:I,"Dez/25") -> 2477.48 | E10: =AVERAGE(B10:D10) -> 4440.01 | F10: Extrato: Categoria=Receita Financeira
A11: (+) Estornos | B11: =SUMIFS(Extrato_Limpo!D:D,Extrato_Limpo!G:G,"Estorno",Extrato_Limpo!I:I,"Out/25") -> 6318.67 | C11: =SUMIFS(Extrato_Limpo!D:D,Extrato_Limpo!G:G,"Estorno",Extrato_Limpo!I:I,"Nov/25") -> 9506.81 | D11: =SUMIFS(Extrato_Limpo!D:D,Extrato_Limpo!G:G,"Estorno",Extrato_Limpo!I:I,"Dez/25") -> 1170.1 | E11: =AVERAGE(B11:D11) -> 5665.1933 | F11: Extrato: Categoria=Estorno
A12: (info) Transferências Internas | B12: =SUMIFS(Extrato_Limpo!D:D,Extrato_Limpo!G:G,"Transferência Interna",Extrato_Limpo!I:I,"Out/25") -> -517401.13 | C12: =SUMIFS(Extrato_Limpo!D:D,Extrato_Limpo!G:G,"Transferência Interna",Extrato_Limpo!I:I,"Nov/25") -> -723592.84 | D12: =SUMIFS(Extrato_Limpo!D:D,Extrato_Limpo!G:G,"Transferência Interna",Extrato_Limpo!I:I,"Dez/25") -> -533001.95 | E12: =AVERAGE(B12:D12) -> -591331.97 | F12: Informativo — não incluso no saldo final
A14: (=) Variação de Caixa | B14: =B7+B9+B10+B11 -> 1351114.7 | C14: =C7+C9+C10+C11 -> 3940911.8 | D14: =D7+D9+D10+D11 -> 4133320.3 | E14: =AVERAGE(B14:D14) -> 3141782.3
A15: (=) Saldo Final | B15: =B3+B14 -> 4201114.7 | C15: =B15+C14 -> 8142026.5 | D15: =C15+D14 -> 12275347 | E15: =AVERAGE(B15:D15) -> 8206162.7
A17: Burn Rate Mensal (Líquido) | B17: =-B14 -> -1351114.7 | C17: =-C14 -> -3940911.8 | D17: =-D14 -> -4133320.3 | E17: =AVERAGE(B17:D17) -> -3141782.3 | F17: Negativo do Fluxo Oper. + Financeiro
A18: Runway (meses) | B18: =IF(B17<=0,"N/A",B15/B17) -> N/A | C18: =IF(C17<=0,"N/A",C15/C17) -> N/A | D18: =IF(D17<=0,"N/A",D15/D17) -> N/A | E18: =AVERAGE(B18:D18) -> #DIV/0! | F18: Saldo Final / |Burn Rate|. N/A se burn≤0

Sheet AP_AR_Anotado
A1: Tipo | B1: Fornecedor/Cliente | C1: Descrição | D1: Valor (R$) | E1: Vencimento | F1: Status | G1: Dias em Atraso | H1: Centro de Custo | I1: Observação | J1: Ação Recomendada | K1: Prioridade | L1: Recebido_no_Extrato
A2: AR | B2: Beta SaaS | C2: NF 1038 - MRR Nov/25 | D2: 38000 | E2: 45976 | F2: Vencida | G2: 46 | H2: Comercial | I2: Cliente churnou, cobrança em aberto | J2: Acionar jurídico para cobrança — cliente churnou | K2: Alta | L2: =SUMIFS(Extrato_Limpo!D:D,Extrato_Limpo!G:G,"Receita de Cliente",Extrato_Limpo!B:B,"*BETA SAAS*") -> 1261517.7
A3: AR | B3: Delta Cloud | C3: NF 1055 - MRR Out/25 | D3: 18000 | E3: 45950 | F3: Vencida | G3: 72 | H3: Comercial | I3: Downgrade não refletido na NF | J3: Emitir NF corrigida (R$15k) e negociar diferença de R$3k | K3: Alta | L3: =SUMIFS(Extrato_Limpo!D:D,Extrato_Limpo!G:G,"Receita de Cliente",Extrato_Limpo!B:B,"*DELTA CLOUD*") -> 787246.79
A4: AR | B4: Mu Analytics | C4: NF 1048 - MRR Out/25 | D4: 19000 | E4: 45955 | F4: Vencida | G4: 67 | H4: Comercial | I4: NF emitida mas não enviada ao cliente | J4: Enviar NF imediatamente ao cliente | K4: Alta | L4: 0
A5: AR | B5: Alpha Tech | C5: NF 1042 - MRR Dez/25 | D5: 45000 | E5: 46032 | F5: A Vencer | G5: 0 | H5: Comercial | J5: Monitorar — a vencer, NF pendente há 3 meses | K5: Média | L5: =SUMIFS(Extrato_Limpo!D:D,Extrato_Limpo!G:G,"Receita de Cliente",Extrato_Limpo!B:B,"*ALPHA TECH*") -> 2040122.6
A6: AR | B6: Epsilon Data | C6: NF 1060 - MRR Dez/25 | D6: 55000 | E6: 46032 | F6: A Vencer | G6: 0 | H6: Comercial | J6: A vencer — acompanhar recebimento | K6: Baixa | L6: =SUMIFS(Extrato_Limpo!D:D,Extrato_Limpo!G:G,"Receita de Cliente",Extrato_Limpo!B:B,"*EPSILON DATA*") -> 1249542.4
A7: AR | B7: Pi Logistics | C7: NF 1082 - MRR Nov/25 | D7: 7500 | E7: 45996 | F7: Vencida | G7: 26 | H7: Comercial | I7: Risco alto de churn | J7: Contato comercial urgente + cobrança | K7: Alta | L7: 0
A8: AR | B8: Gamma Digital | C8: NF 1051 - Setup | D8: 15000 | E8: 45991 | F8: Vencida | G8: 31 | H8: Comercial | I8: Cobrança de setup nunca enviada | J8: Enviar cobrança de setup (nunca enviada) | K8: Média | L8: =SUMIFS(Extrato_Limpo!D:D,Extrato_Limpo!G:G,"Receita de Cliente",Extrato_Limpo!B:B,"*GAMMA DIGITAL*") -> 321814.66
A9: AP | B9: AWS | C9: Infraestrutura Cloud - Dez/25 | D9: 95000 | E9: 46027 | F9: A Vencer | G9: 0 | H9: Infraestrutura | I9: Aumento de 17% vs Out | J9: Monitorar — aumento 17% vs Out, a vencer | K9: Média
A10: AP | B10: Google Cloud | C10: GCP - Dez/25 | D10: 32000 | E10: 46032 | F10: A Vencer | G10: 0 | H10: Infraestrutura | J10: A vencer — acompanhar fatura | K10: Baixa
A11: AP | B11: WeWork | C11: Aluguel Jan/26 | D11: 15000 | E11: 46027 | F11: A Vencer | G11: 0 | H11: G&A | J11: A vencer — pagamento normal | K11: Baixa
A12: AP | B12: Unimed | C12: Plano Saúde Equipe - Jan/26 | D12: 28000 | E12: 46032 | F12: A Vencer | G12: 0 | H12: Benefícios | J12: A vencer — pagamento normal | K12: Baixa
A13: AP | B13: Freelancer A | C13: Desenvolvimento Feature X | D13: 18000 | E13: 46006 | F13: Vencida | G13: 16 | H13: Engenharia | I13: Sem contrato formal | J13: Regularizar contrato formal antes de pagar | K13: Alta
A14: AP | B14: Freelancer B | C14: Design Sprint Q4 | D14: 12000 | E14: 45991 | F14: Vencida | G14: 31 | H14: Produto | I14: NF não emitida pelo fornecedor | J14: Solicitar NF ao fornecedor antes de pagar | K14: Média
A15: AP | B15: Silva & Advogados | C15: Honorários Q4 | D15: 36000 | E15: 46011 | F15: Vencida | G15: 11 | H15: G&A | I15: Cobrança contestada - valor diverge do contrato | J15: Revisar contrato e alinhar valor contestado | K15: Alta
A16: AP | B16: Receita Federal | C16: DAS Simples - Dez/25 | D16: 31237 | E16: 46042 | F16: A Vencer | G16: 0 | H16: G&A | J16: A vencer — garantir pagamento em dia (DAS) | K16: Média
A17: AP | B17: Folha | C17: 13o Salário - 2a parcela | D17: 97500 | E17: 46011 | F17: Paga | G17: 0 | H17: Pessoal | I17: Paga com 2 dias de atraso | J17: Pago com atraso — registrar ocorrência RH | K17: Baixa

Sheet Dashboard
A1: 1. RECEITA REAL VS. REPORTADA (Q4 2025)
B2: DRE Original | C2: DRE Corrigida | D2: Diferença | E2: Ratio
A3: Receita Bruta Out/25 | B3: 442000 | C3: =DRE_Corrigida!B3 -> 4432710.5 | D3: =C3-B3 -> 3990710.5 | E3: =IF(B3=0,"N/A",C3/B3) -> 10.028757
A4: Receita Bruta Nov/25 | B4: 435500 | C4: =DRE_Corrigida!C3 -> 3956495.7 | D4: =C4-B4 -> 3520995.7 | E4: =IF(B4=0,"N/A",C4/B4) -> 9.08495
A5: Receita Bruta Dez/25 | B5: 416500 | C5: =DRE_Corrigida!D3 -> 2309191.5 | D5: =C5-B5 -> 1892691.5 | E5: =IF(B5=0,"N/A",C5/B5) -> 5.5442774
A6: Receita Bruta Q4 | B6: 1294000 | C6: =DRE_Corrigida!E3 -> 10698398 | D6: =C6-B6 -> 9404397.8 | E6: =IF(B6=0,"N/A",C6/B6) -> 8.2676954
A9: 2. SAÚDE DO CAIXA
A10: Saldo Inicial Out/25 (extrato) | B10: =Caixa_Corrigido!B3 -> 2850000
A11: Saldo Final Dez/25 (extrato) | B11: =Caixa_Corrigido!D15 -> 12275347
A12: Entradas Operacionais Q4 | B12: =Caixa_Corrigido!B5+Caixa_Corrigido!C5+Caixa_Corrigido!D5 -> 10500044
A13: Saídas Operacionais Q4 | B13: =Caixa_Corrigido!B6+Caixa_Corrigido!C6+Caixa_Corrigido!D6 -> -4105012.9
A14: Aporte Investidores Q4 | B14: =Caixa_Corrigido!B9+Caixa_Corrigido!C9+Caixa_Corrigido!D9 -> 3000000
A15: Burn Rate Médio Mensal | B15: =AVERAGE(Caixa_Corrigido!B17:D17) -> -3141782.3
A16: Runway (Dez/25, meses) | B16: =Caixa_Corrigido!D18 -> N/A
A19: 3. ALERTAS E FLAGS
A20: NFs Duplicadas (ERP) | B20: =COUNTIF(ERP_Limpo!M:M,"DUPLICADA") -> 47 | C20: NFs com mesmo número em clientes diferentes
A21: Despesas sem Documento (ERP) | B21: =COUNTIF(ERP_Limpo!N:N,"SEM DOCUMENTO") -> 34 | C21: Despesas sem NF ou comprovante
A22: Lançamentos com Competência Divergente | B22: =COUNTIF(ERP_Limpo!L:L,"DIVERGENTE") -> 85 | C22: Data competência ≠ mês de lançamento
A23: Lançamentos não Conciliados (ERP) | B23: =COUNTIFS(ERP_Limpo!I:I,"<>Conciliado",ERP_Limpo!A:A,"<>") -> 105 | C23: Status Pendente + Divergente + Em Aberto
A24: AR Vencido (R$) | B24: =SUMIFS(AP_AR_Anotado!D:D,AP_AR_Anotado!A:A,"AR",AP_AR_Anotado!F:F,"Vencida") -> 97500 | C24: Contas a receber vencidas
A25: AP Vencido (R$) | B25: =SUMIFS(AP_AR_Anotado!D:D,AP_AR_Anotado!A:A,"AP",AP_AR_Anotado!F:F,"Vencida") -> 66000 | C25: Contas a pagar vencidas
A26: Clientes sem Recebimento no Extrato Q4 | B26: 6 | C26: Lambda Fin, Mu Analytics, Nu Robotics, Omicron Health, Pi Logistics, Rho Security
